data loaded!
lr: 0.0001
Epoch 0/1000 | Avg Loss: 0.094449
Epoch 10/1000 | Avg Loss: 0.000273
Epoch 20/1000 | Avg Loss: 0.000095
Epoch 30/1000 | Avg Loss: 0.000070
Epoch 40/1000 | Avg Loss: 0.000048
Epoch 50/1000 | Avg Loss: 0.000040
Epoch 60/1000 | Avg Loss: 0.000039
Epoch 70/1000 | Avg Loss: 0.000036
Epoch 80/1000 | Avg Loss: 0.000034
Epoch 90/1000 | Avg Loss: 0.000030
Epoch 100/1000 | Avg Loss: 0.000025
Epoch 110/1000 | Avg Loss: 0.000025
Epoch 120/1000 | Avg Loss: 0.000021
Epoch 130/1000 | Avg Loss: 0.000023
Epoch 140/1000 | Avg Loss: 0.000022
Epoch 150/1000 | Avg Loss: 0.000020
Epoch 160/1000 | Avg Loss: 0.000019
Epoch 170/1000 | Avg Loss: 0.000020
Epoch 180/1000 | Avg Loss: 0.000016
Epoch 190/1000 | Avg Loss: 0.000015
Epoch 200/1000 | Avg Loss: 0.000018
Epoch 210/1000 | Avg Loss: 0.000016
Epoch 220/1000 | Avg Loss: 0.000014
Epoch 230/1000 | Avg Loss: 0.000013
Epoch 240/1000 | Avg Loss: 0.000012
Epoch 250/1000 | Avg Loss: 0.000012
Epoch 260/1000 | Avg Loss: 0.000012
Epoch 270/1000 | Avg Loss: 0.000011
Epoch 280/1000 | Avg Loss: 0.000012
Epoch 290/1000 | Avg Loss: 0.000011
Epoch 300/1000 | Avg Loss: 0.000010
Epoch 310/1000 | Avg Loss: 0.000011
Epoch 320/1000 | Avg Loss: 0.000010
Epoch 330/1000 | Avg Loss: 0.000010
Epoch 340/1000 | Avg Loss: 0.000010
Epoch 350/1000 | Avg Loss: 0.000010
Traceback (most recent call last):
  File "/home/gmh72/.conda/envs/TensoIR3/lib/python3.8/site-packages/PIL/ImageFile.py", line 547, in _save
    fh = fp.fileno()
AttributeError: '_idat' object has no attribute 'fileno'

During handling of the above exception, another exception occurred:

Traceback (most recent call last):
  File "pixel.py", line 221, in <module>
    train(model, dataloader, config, device)
  File "pixel.py", line 184, in train
    generate_reflectance_image(model, dataset)
  File "pixel.py", line 75, in generate_reflectance_image
    figure_label: wandb.Image(labeled, caption=label),
  File "/home/gmh72/.conda/envs/TensoIR3/lib/python3.8/site-packages/wandb/sdk/data_types/image.py", line 179, in __init__
    self._initialize_from_data(data_or_path, mode, file_type)
  File "/home/gmh72/.conda/envs/TensoIR3/lib/python3.8/site-packages/wandb/sdk/data_types/image.py", line 336, in _initialize_from_data
    self._image.save(tmp_path, transparency=None)
  File "/home/gmh72/.conda/envs/TensoIR3/lib/python3.8/site-packages/PIL/Image.py", line 2568, in save
    save_handler(self, fp, filename)
  File "/home/gmh72/.conda/envs/TensoIR3/lib/python3.8/site-packages/PIL/PngImagePlugin.py", line 1431, in _save
    ImageFile._save(im, _idat(fp, chunk), [("zip", (0, 0) + im.size, 0, rawmode)])
  File "/home/gmh72/.conda/envs/TensoIR3/lib/python3.8/site-packages/PIL/ImageFile.py", line 551, in _save
    _encode_tile(im, fp, tile, bufsize, None, exc)
  File "/home/gmh72/.conda/envs/TensoIR3/lib/python3.8/site-packages/PIL/ImageFile.py", line 570, in _encode_tile
    errcode, data = encoder.encode(bufsize)[1:]
KeyboardInterrupt
